Workbook

Sheet Payroll Dec 2025
A1: SINARAN PRECISION SDN BHD
A2: Payroll & Headcount Register - Month: December 2025
A3: Extracted from: HR shared drive \\SPSB-FS01\HR\Payroll\2025 | Last edited: 08/01/2026 by S. Aishah
A5: Staff ID | B5: Employee Name | C5: Department | D5: Gender | E5: Nationality | F5: Employment Type | G5: Date Joined | H5: Date Left | I5: Basic Salary (RM) | J5: Fixed Allowance (RM) | K5: EPF Employer (RM) | L5: SOCSO Employer (RM) | M5: Training Hours 2025 | N5: Safety Induction Completed
A6: SP-0001 | B6: Ahmad Faizal bin Osman | C6: Production | D6: M | E6: Malaysian | F6: Permanent | G6: 42443 | I6: 3200 | J6: 350 | K6: =ROUND((I6+J6)*0.13,2) -> 461.5 | L6: =ROUND((I6+J6)*0.0175,2) -> 62.13 | M6: 12 | N6: Yes
A7: SP-0002 | B7: Lim Wei Ling | C7: Admin | D7: F | E7: Malaysian | F7: Permanent | G7: 42887 | I7: 3800 | J7: 400 | K7: =ROUND((I7+J7)*0.13,2) -> 546 | L7: =ROUND((I7+J7)*0.0175,2) -> 73.5 | M7: 8 | N7: Yes
A8: SP-0003 | B8: Raj Kumar a/l Subramaniam | C8: Production | D8: M | E8: Malaysian | F8: Permanent | G8: 42023 | I8: 3450 | J8: 350 | K8: =ROUND((I8+J8)*0.13,2) -> 494 | L8: =ROUND((I8+J8)*0.0175,2) -> 66.5 | N8: Yes
A9: SP-0004 | B9: Nurul Aina binti Zulkifli | C9: QA | D9: F | E9: Malaysian | F9: Permanent | G9: 43710 | I9: 3100 | J9: 300 | K9: =ROUND((I9+J9)*0.13,2) -> 442 | L9: =ROUND((I9+J9)*0.0175,2) -> 59.5 | M9: 16 | N9: Yes
A10: SP-0005 | B10: Tan Chee Keong | C10: Production | D10: M | E10: Malaysian | F10: Permanent | G10: 41736 | I10: 4100 | J10: 450 | K10: =ROUND((I10+J10)*0.13,2) -> 591.5 | L10: =ROUND((I10+J10)*0.0175,2) -> 79.63 | M10: 6 | N10: Yes
A11: SP-0006 | B11: Mohd Hafiz bin Ismail | C11: PRODUCTION | D11: M | E11: Malaysian | F11: Permanent | G11: 43416 | I11: 2950 | J11: 300 | K11: =ROUND((I11+J11)*0.13,2) -> 422.5 | L11: =ROUND((I11+J11)*0.0175,2) -> 56.88 | N11: Yes
A12: SP-0007 | B12: Siti Aishah binti Rahman | C12: HR | D12: F | E12: Malaysian | F12: Permanent | G12: 43878 | I12: 4200 | J12: 500 | K12: =ROUND((I12+J12)*0.13,2) -> 611 | L12: =ROUND((I12+J12)*0.0175,2) -> 82.25 | M12: 24 | N12: Yes
A13: SP-0008 | B13: Kavitha a/p Ganesan | C13: Finance | D13: F | E13: Malaysian | F13: Permanent | G13: 43591 | I13: 4500 | J13: 500 | K13: =ROUND((I13+J13)*0.13,2) -> 650 | L13: =ROUND((I13+J13)*0.0175,2) -> 87.5 | M13: 20 | N13: Yes
A14: SP-0009 | B14: Md Rasel Hossain | C14: Production | D14: M | E14: Bangladeshi | F14: Contract | G14: 44788 | I14: 1700 | J14: 200 | K14: =ROUND((I14+J14)*0.13,2) -> 247 | L14: =ROUND((I14+J14)*0.0175,2) -> 33.25 | N14: Yes
A15: SP-0010 | B15: Abdul Karim Miah | C15: Production | D15: M | E15: Bangladeshi | F15: Contract | G15: 44788 | I15: 1750 | J15: 200 | K15: =ROUND((I15+J15)*0.13,2) -> 253.5 | L15: =ROUND((I15+J15)*0.0175,2) -> 34.13 | N15: No
A16: SP-0011 | B16: Wong Mei Chen | C16: Admin | D16: F | E16: Malaysian | F16: Permanent | G16: 44207 | I16: 3300 | J16: 350 | K16: =ROUND((I16+J16)*0.13,2) -> 474.5 | L16: =ROUND((I16+J16)*0.0175,2) -> 63.88 | M16: 10 | N16: Yes
A17: SP-0012 | B17: Zulkarnain bin Yusof | C17: Maintenance | D17: M | E17: Malaysian | F17: Permanent | G17: 43011 | I17: 3600 | J17: 400 | K17: =ROUND((I17+J17)*0.13,2) -> 520 | L17: =ROUND((I17+J17)*0.0175,2) -> 70 | M17: 14 | N17: Yes
A18: SP-0013 | B18: Nor Hidayah binti Salleh | C18: QA | D18: F | E18: Malaysian | F18: Permanent | G18: 44032 | I18: 3050 | J18: 300 | K18: =ROUND((I18+J18)*0.13,2) -> 435.5 | L18: =ROUND((I18+J18)*0.0175,2) -> 58.63 | M18: 16 | N18: Yes
A19: SP-0014 | B19: Chandran a/l Muthu | C19: Production | D19: M | E19: Malaysian | F19: Permanent | G19: 42709 | I19: 3400 | J19: 350 | K19: =ROUND((I19+J19)*0.13,2) -> 487.5 | L19: =ROUND((I19+J19)*0.0175,2) -> 65.63 | N19: Yes
A20: SP-0015 | B20: Farah Diana binti Kamal | C20: Sales | D20: F | E20: Malaysian | F20: Permanent | G20: 44284 | I20: 3900 | J20: 600 | K20: =ROUND((I20+J20)*0.13,2) -> 585 | L20: =ROUND((I20+J20)*0.0175,2) -> 78.75 | M20: 12 | N20: Yes
A21: SP-0016 | B21: Lee Chong Wei | C21: Production | D21: M | E21: Malaysian | F21: Permanent | G21: 12/3/2021 | I21: 3150 | J21: 300 | K21: =ROUND((I21+J21)*0.13,2) -> 448.5 | L21: =ROUND((I21+J21)*0.0175,2) -> 60.38 | M21: 8 | N21: Yes
A22: SP-0017 | B22: Bikash Tamang | C22: Production | D22: M | E22: Nepali | F22: Contract | G22: 44963 | I22: 1850 | J22: 200 | K22: =ROUND((I22+J22)*0.13,2) -> 266.5 | L22: =ROUND((I22+J22)*0.0175,2) -> 35.88 | N22: Yes
A23: SP-0018 | B23: Suresh Gurung | C23: Production | D23: M | E23: Nepali | F23: Contract | G23: 44963 | I23: 1850 | J23: 200 | K23: =ROUND((I23+J23)*0.13,2) -> 266.5 | L23: =ROUND((I23+J23)*0.0175,2) -> 35.88 | M23: 4 | N23: Yes
A24: SP-0019 | B24: Aminah binti Hassan | C24: Admin | D24: F | E24: Malaysian | F24: Permanent | G24: 44697 | I24: 2900 | J24: 300 | K24: =ROUND((I24+J24)*0.13,2) -> 416 | L24: =ROUND((I24+J24)*0.0175,2) -> 56 | M24: 8 | N24: Yes
A25: SP-0020 | B25: Goh Boon Huat | C25: Maintenance | D25: M | E25: Malaysian | F25: Permanent | G25: 43339 | I25: 3550 | J25: 400 | K25: =ROUND((I25+J25)*0.13,2) -> 513.5 | L25: =ROUND((I25+J25)*0.0175,2) -> 69.13 | N25: Yes
A26: SP-0021 | B26: Nurhaliza binti Awang | C26: QA | E26: Malaysian | F26: Permanent | G26: 44452 | I26: 3000 | J26: 300 | K26: =ROUND((I26+J26)*0.13,2) -> 429 | L26: =ROUND((I26+J26)*0.0175,2) -> 57.75 | M26: 16 | N26: Yes
A27: SP-0022 | B27: Mohd Syafiq bin Rosli | C27: Prod. | D27: M | E27: Malaysian | F27: Permanent | G27: 43563 | I27: 3250 | J27: 350 | K27: =ROUND((I27+J27)*0.13,2) -> 468 | L27: =ROUND((I27+J27)*0.0175,2) -> 63 | M27: 6 | N27: Yes
A28: SP-0023 | B28: Ng Sook Fun | C28: Finance | D28: F | E28: Malaysian | F28: Permanent | G28: 44137 | I28: 4000 | J28: 450 | K28: =ROUND((I28+J28)*0.13,2) -> 578.5 | L28: =ROUND((I28+J28)*0.0175,2) -> 77.88 | M28: 20 | N28: Yes
A29: SP-0024 | B29: Ismail bin Jaafar | C29: Production | D29: M | E29: Malaysian | F29: Permanent | G29: Mar-2019 | I29: 3350 | J29: 350 | K29: =ROUND((I29+J29)*0.13,2) -> 481 | L29: =ROUND((I29+J29)*0.0175,2) -> 64.75 | N29: Yes
A30: SP-0025 | B30: Priya a/p Rajendran | C30: Admin | D30: F | E30: Malaysian | F30: Permanent | G30: 44585 | I30: 2850 | J30: 300 | K30: =ROUND((I30+J30)*0.13,2) -> 409.5 | L30: =ROUND((I30+J30)*0.0175,2) -> 55.13 | M30: 8 | N30: Yes
A31: SP-0026 | B31: Khairul Anuar bin Daud | C31: Production | D31: M | E31: Malaysian | F31: Permanent | G31: 42779 | I31: 3500 | J31: 350 | K31: =ROUND((I31+J31)*0.13,2) -> 500.5 | L31: =ROUND((I31+J31)*0.0175,2) -> 67.38 | M31: 12 | N31: Yes
A32: SP-0027 | B32: Yap Kim Seng | C32: Sales | D32: M | E32: Malaysian | F32: Permanent | G32: 43626 | I32: 4300 | J32: 700 | K32: =ROUND((I32+J32)*0.13,2) -> 650 | L32: =ROUND((I32+J32)*0.0175,2) -> 87.5 | M32: 12 | N32: Yes
A33: SP-0028 | B33: Rohana binti Mat Nor | C33: HR | D33: F | E33: Malaysian | F33: Permanent | G33: 44410 | I33: 3200 | J33: 350 | K33: =ROUND((I33+J33)*0.13,2) -> 461.5 | L33: =ROUND((I33+J33)*0.0175,2) -> 62.13 | M33: 24 | N33: Yes
A34: SP-0029 | B34: Sivakumar a/l Perumal | C34: Maintenance | D34: M | E34: Malaysian | F34: Permanent | G34: 42520 | I34: 3700 | J34: 400 | K34: =ROUND((I34+J34)*0.13,2) -> 533 | L34: =ROUND((I34+J34)*0.0175,2) -> 71.75 | N34: Yes
A35: SP-0030 | B35: Norazlina binti Ahmad | C35: QA | E35: Malaysian | F35: Permanent | G35: 45005 | I35: 2800 | J35: 300 | K35: =ROUND((I35+J35)*0.13,2) -> 403 | L35: =ROUND((I35+J35)*0.0175,2) -> 54.25 | M35: 16 | N35: Yes
A36: SP-0031 | B36: Chong Ah Meng | C36: Production | D36: M | E36: Malaysian | F36: Permanent | G36: 43115 | I36: 3300 | J36: 350 | K36: =ROUND((I36+J36)*0.13,2) -> 474.5 | L36: =ROUND((I36+J36)*0.0175,2) -> 63.88 | M36: 8 | N36: Yes
A37: SP-0031 | B37: Chong Ah Meng | C37: PRODUCTION | D37: M | E37: Malaysian | F37: Permanent | G37: 43115 | I37: 3300 | J37: 350 | K37: =ROUND((I37+J37)*0.13,2) -> 474.5 | L37: =ROUND((I37+J37)*0.0175,2) -> 63.88 | M37: 8 | N37: Yes
A38: SP-0032 | B38: Hafizah binti Omar | C38: Admin | E38: Malaysian | F38: Permanent | G38: 44809 | I38: 2750 | J38: 300 | K38: =ROUND((I38+J38)*0.13,2) -> 396.5 | L38: =ROUND((I38+J38)*0.0175,2) -> 53.38 | N38: Yes
A39: SP-0033 | B39: Ravi a/l Krishnan | C39: Production | D39: M | E39: Malaysian | F39: Permanent | G39: 43901 | I39: 3150 | J39: 300 | K39: =ROUND((I39+J39)*0.13,2) -> 448.5 | L39: =ROUND((I39+J39)*0.0175,2) -> 60.38 | M39: 6 | N39: Yes
A40: SP-0034 | B40: Shahrul Nizam bin Abdullah | C40: Production | D40: M | E40: Malaysian | F40: Resigned | G40: 43668 | I40: 3250 | J40: 350 | K40: =ROUND((I40+J40)*0.13,2) -> 468 | L40: =ROUND((I40+J40)*0.0175,2) -> 63 | M40: 6 | N40: Yes
A41: SP-0035 | B41: Teoh Li Ping | C41: Finance | D41: F | E41: Malaysian | F41: Permanent | G41: 44536 | I41: 3850 | J41: 400 | K41: =ROUND((I41+J41)*0.13,2) -> 552.5 | L41: =ROUND((I41+J41)*0.0175,2) -> 74.38 | M41: 20 | N41: Yes
...

Sheet Summary
A1: HR Summary - FY2025
A2: Prepared for customer ESG questionnaire response
A4: Metric | B4: Value | C4: Note / Source
A5: Headcount per HR system (Dec 2025) | B5: 45 | C5: Typed in from HRMS screen by S. Aishah - not reconciled
A6: Rows present in this register | B6: =COUNTA('Payroll Dec 2025'!A6:A48) -> 43 | C6: Counted from the register itself
A7: Unique Staff IDs in register | B7: =SUMPRODUCT(1/COUNTIF('Payroll Dec 2025'!A6:A48,'Payroll Dec 2025'!A6:A48)) -> 42 | C7: Duplicate IDs will make this lower than row count
A9: Employees recorded as Male | B9: =COUNTIF('Payroll Dec 2025'!D6:D48,"M") -> 24
A10: Employees recorded as Female | B10: =COUNTIF('Payroll Dec 2025'!D6:D48,"F") -> 15
A11: Gender field BLANK | B11: =COUNTBLANK('Payroll Dec 2025'!D6:D48) -> 4 | C11: Cannot report gender split until filled
A12: Female share of recorded workforce | B12: =IFERROR(COUNTIF('Payroll Dec 2025'!D6:D48,"F")/(COUNTIF('Payroll Dec 2025'!D6:D48,"M")+COUNTIF('Payroll Dec 2025'!D6:D48,"F")),"n/a") -> 0.38461538 | C12: Excludes blanks - may misstate the true split
A14: Total basic salary paid (RM/month) | B14: =SUM('Payroll Dec 2025'!I6:I48) -> 137100
A15: Average basic salary (RM/month) | B15: =IFERROR(AVERAGE('Payroll Dec 2025'!I6:I48),"n/a") -> 3188.3721
A16: Lowest basic salary (RM/month) | B16: =MIN('Payroll Dec 2025'!I6:I48) -> 1700
A17: Staff below RM1,700 statutory minimum wage | B17: =COUNTIF('Payroll Dec 2025'!I6:I48,"<1700") -> 0 | C17: Minimum wage RM1,700/month, Minimum Wages Order 2024
A19: Total recorded training hours 2025 | B19: =SUM('Payroll Dec 2025'!M6:M48) -> 372 | C19: Blank cells are excluded, not counted as zero
A20: Staff with NO training hours recorded | B20: =COUNTBLANK('Payroll Dec 2025'!M6:M48) -> 12 | C20: Unknown - not confirmed as zero training
A21: Average training hours per recorded staff | B21: =IFERROR(AVERAGE('Payroll Dec 2025'!M6:M48),"n/a") -> 12 | C21: Based only on staff with a value
A23: Safety induction NOT completed | B23: =COUNTIF('Payroll Dec 2025'!N6:N48,"No") -> 2
A24: Number of distinct department labels | B24: =SUMPRODUCT(1/COUNTIF('Payroll Dec 2025'!C6:C48,'Payroll Dec 2025'!C6:C48)) -> 9 | C24: Higher than the real number of departments - labels are inconsistent
A26: NOT AVAILABLE IN THIS FILE
A27: Workplace injury / lost-time incident (LTI) count 2025 | B27: - | C27: No source document provided
A28: Employee turnover rate 2025 (leavers not recorded) | B28: - | C28: No source document provided
A29: Overtime hours 2025 | B29: - | C29: No source document provided
A30: Union / worker representation status | B30: - | C30: No source document provided

Sheet Notes
A1: SINARAN PRECISION SDN BHD - HR Register Notes
A3: This register is maintained manually on the HR shared drive and updated monthly.
A4: It has not been reconciled against the HRMS since August 2025.
A6: Legend:
A7: Blue text on yellow fill = value typed in by hand (not calculated)
A8: Black text = calculated by formula from the register
A9: A blank Training Hours cell means NOT RECORDED. It does not mean zero hours.
A11: Known issues flagged by Finance during the Nov 2025 audit and not yet fixed:
A12: - Headcount in this file does not tie to the HRMS figure.
A13: - Leaver dates are not being captured when staff resign.
A14: - Department names are typed free-hand, so the same department appears several ways.
A16: MOCK DOCUMENT - SYNTHETIC TEST DATA FOR HACKATHON USE ONLY.
